<?xml version="1.0" ?>
<!-- =================================================================================== -->
<!-- |    This document was autogenerated by xacro from zimmer_description.xacro       | -->
<!-- |    EDITING THIS FILE BY HAND IS NOT RECOMMENDED                                 | -->
<!-- =================================================================================== -->
<robot name="zimmer_description">
  <material name="silver">
    <color rgba="0.700 0.700 0.700 1.000"/>
  </material>
  <!-- <xacro:include filename="$(find zimmer_description)/urdf/zimmer_description.trans" /> -->
  <!-- <xacro:include filename="$(find zimmer_description)/urdf/zimmer_description.gazebo" /> -->
  <link name="base_link">
    <inertial>
      <origin rpy="0 0 0" xyz="0.0001004407776845725 -3.782256688140103e-16 0.05878685212370678"/>
      <mass value="2.9848284063454846"/>
      <inertia ixx="0.003517" ixy="-0.0" ixz="1.1e-05" iyy="0.005044" iyz="-0.0" izz="0.002589"/>
    </inertial>
    <visual>
      <origin rpy="0 0 0" xyz="0 0 0"/>
      <geometry>
        <mesh filename="file://../meshes/base_link.stl" scale="0.001 0.001 0.001"/>
      </geometry>
      <material name="silver"/>
    </visual>
    <collision>
      <origin rpy="0 0 0" xyz="0 0 0"/>
      <geometry>
        <mesh filename="file:///meshes/base_link.stl" scale="0.001 0.001 0.001"/>
      </geometry>
    </collision>
  </link>
  <link name="slider_1">
    <inertial>
      <origin rpy="0 0 0" xyz="0 0 0.022639226003290505"/>
      <mass value="0.04981450503853536"/>
      <inertia ixx="1e-06" ixy="-0.0" ixz="0.0" iyy="2.3e-05" iyz="-0.0" izz="2.4e-05"/>
    </inertial>
    <visual>
      <origin rpy="0 0 0" xyz="-0.0 0.01225 -0.0905"/>
      <geometry>
        <mesh filename="file:///home/case/synbio_ws/install/zimmer_description/share/zimmer_description/meshes/SLIDER.stl" scale="0.001 0.001 0.001"/>
      </geometry>
      <material name="silver"/>
    </visual>
    <collision>
      <origin rpy="0 0 0" xyz="-0.0 0.01225 -0.0905"/>
      <geometry>
        <mesh filename="file:///home/case/synbio_ws/install/zimmer_description/share/zimmer_description/meshes/SLIDER.stl" scale="0.001 0.001 0.001"/>
      </geometry>
    </collision>
  </link>
  <joint name="base_to_slider_1" type="prismatic">
    <origin rpy="0 0 0" xyz="0.0 0.01225 0.0905"/>
    <parent link="base_link"/>
    <child link="slider_1"/>
    <axis xyz="1.0 0.0 0.0"/>
    <limit effort="100" lower="-0.0105" upper="0.0105" velocity="100"/>
  </joint>
  <link name="slider_2">
    <inertial>
      <origin rpy="0 0 0" xyz="0 0 0.022639226003290505"/>
      <mass value="0.04981450503853536"/>
      <inertia ixx="1e-06" ixy="-0.0" ixz="0.0" iyy="2.3e-05" iyz="-0.0" izz="2.4e-05"/>
    </inertial>
    <visual>
      <origin rpy="0 0 0" xyz="-0.0 -0.01225 -0.0905"/>
      <geometry>
        <mesh filename="file:///home/case/synbio_ws/install/zimmer_description/share/zimmer_description/meshes/SLIDER.stl" scale="0.001 0.001 0.001"/>
      </geometry>
      <material name="silver"/>
    </visual>
    <collision>
      <origin rpy="0 0 0" xyz="-0.0 -0.01225 -0.0905"/>
      <geometry>
        <mesh filename="file:///home/case/synbio_ws/install/zimmer_description/share/zimmer_description/meshes/SLIDER.stl" scale="0.001 0.001 0.001"/>
      </geometry>
    </collision>
  </link>
  <joint name="base_to_slider_2" type="prismatic">
    <origin rpy="0 0 0" xyz="0.0 -0.01225 0.0905"/>
    <parent link="base_link"/>
    <child link="slider_2"/>
    <axis xyz="1.0 0.0 0.0"/>
    <limit effort="100" lower="-0.0105" upper="0.0105" velocity="100"/>
  </joint>
</robot>
