<?xml version="1.0" ?>
<robot name="zimmer_description" xmlns:xacro="http://www.ros.org/wiki/xacro">

<xacro:include filename="$(find zimmer_description)/urdf/materials.xacro" />
<xacro:include filename="$(find zimmer_description)/urdf/zimmer_description.trans" />
<!-- <xacro:include filename="$(find zimmer_description)/urdf/zimmer_description.gazebo" /> -->


<xacro:property name="y_origin" value="0.01225" />


<!-- ZIMMER BASE MACRO -->
<xacro:macro name="zimmer_base" params="prefix parent">
  <link name="${prefix}base_link">
    <inertial>
      <origin xyz="0 0 0" rpy="0 0 0"/>
      <mass value="2.9848284063454846"/>
      <inertia ixx="0.003517" iyy="0.005044" izz="0.002589" ixy="-0.0" iyz="-0.0" ixz="1.1e-05"/>
    </inertial>
    <visual>
      <origin xyz="0 0 0" rpy="0 0 0"/>
      <geometry>
        <mesh filename="file://$(find zimmer_description)/meshes/base_link.stl" scale="0.001 0.001 0.001"/>
      </geometry>
      <material name="silver"/>
    </visual>
    <collision>
      <origin xyz="0 0 0" rpy="0 0 0"/>
      <geometry>
        <mesh filename="file://$(find zimmer_description)/meshes/base_link.stl" scale="0.001 0.001 0.001"/>
      </geometry>
    </collision>
  </link>
  <joint name="${prefix}base_link_joint" type="fixed">
    <origin xyz="0 0 0" rpy="0 0 0"/>
    <parent link="${parent}"/>
    <child link="${prefix}base_link"/>
  </joint>

</xacro:macro>

<!-- SLIDER MACRO -->
<xacro:macro name="slider" params="jaw reflect prefix">

  <link name="${prefix}slider_${jaw}">
   <inertial>
      <origin xyz="0 0 0.022639226003290505" rpy="0 0 0"/>
      <mass value="0.04981450503853536"/>
      <inertia ixx="1e-06" iyy="2.3e-05" izz="2.4e-05" ixy="-0.0" iyz="-0.0" ixz="0.0"/>
    </inertial>
    <visual>
      <origin xyz="-0.0 ${y_origin} -0.0905" rpy="0 0 0"/>
      <geometry>
        <mesh filename="file://$(find zimmer_description)/meshes/SLIDER.stl" scale="0.001 0.001 0.001"/>
      </geometry>
      <material name="silver"/>
    </visual>
    <collision>
      <origin xyz="-0.0 ${y_origin} -0.0905" rpy="0 0 0"/>
      <geometry>
        <mesh filename="file://$(find zimmer_description)/meshes/SLIDER.stl" scale="0.001 0.001 0.001"/>
      </geometry>
    </collision>
  </link>

  <joint name="${prefix}slider_${jaw}_joint" type="prismatic">
    <origin xyz="0.0 ${reflect*(y_origin)} 0.0905" rpy="0 0 0"/>
    <parent link="${prefix}base_link"/>
    <child link="${prefix}slider_${jaw}"/>
    <axis xyz="1.0 0.0 0.0"/>
    <limit upper="0.0105" lower="-0.0105" effort="100" velocity="100"/>
  </joint>

</xacro:macro>


</robot>